Workbook
Name BDFRA: [1]!Tabela1[#All]
Name BITA: [2]!Tabela1[#All]
Name BITA: Tabela1[#All]
Name BITA2: [2]!Tabela2[#All]
Name BITA2: Tabela2[#All]
Name BITAC: BDBRA1!$A$1:$DP$1217
Name CGC: [3]brasil!$BO$2:$BO$21
Name CGV: [3]brasil!$BP$2:$BP$21
Name dash: #REF!
Name dash: #REF!
Name ESCUDOS: INDEX(#REF!,MATCH(#REF!,#REF!,0))
Name ESCUDOS: INDEX(#REF!,MATCH(#REF!,#REF!,0))
Name ESCUDOSFORAITALIA: INDEX(#REF!,MATCH(#REF!,#REF!,0))
Name ESCUDOSFORAITALIA: INDEX(#REF!,MATCH(#REF!,#REF!,0))
Name fthg: #REF!
Name fthg: #REF!
Name GFC: [3]brasil!$AU$2:$AU$21
Name MCFC: [3]brasil!$BM$2:$BM$21
Name MCFV: [3]brasil!$BN$2:$BN$21
Name MGFC.: [3]brasil!$AZ$2:$AZ$21
Name MGFV.: [3]brasil!$BA$2:$BA$21
Name NativeTimeline_Date: #N/A
Name NativeTimeline_Date1: #N/A
Name SegmentaçãodeDados_AwayTeam: #N/A
Name SegmentaçãodeDados_AwayTeam1: #N/A
Name SegmentaçãodeDados_AwayTeam2: #N/A
Name SegmentaçãodeDados_FAVC: #N/A
Name SegmentaçãodeDados_FAVV: #N/A
Name SegmentaçãodeDados_HomeTeam: #N/A
Name SegmentaçãodeDados_HomeTeam1: #N/A
Name SegmentaçãodeDados_HomeTeam2: #N/A
Name TT: BDBRA1!$1:$1048576

Sheet INICIO
B9: Bem Vindo! Tutoriais e Links úteis:
B11: Nosso canal no Youtube
B13: Grupo Big Data Bet Telegram
B16: Atualização com botões para cálculo direto dos filtros dash/ todos jogos
B29: Solicite suas planilhas completas e abertas para edição aqui
B30: Para solicitar as planilhas Big Data Bet
B31: ou aqui
B32: Telegram do desenvolvedor
B34: Como habilitar as macros no excel
B35: OBS: Para usar os recursos de botões para zerar filtros, modo noturno, Copiar
B36: médias do dashboard para a aba CS e atualizar somente com macros habilitadas
B38: Ligas Disponíveis:
... B63: Atualizações:
B64: 44985
B65: Aprimoramentos no botão atualizar do dashboard
B66: Aprimoramentos na aba CS Poisson
B67: Novas ligas adicionadas (sulamericanas)
B68: Adicionado previsão de Goleadas e Handicaps Over na aba CS Poisson
B69: Adicionadas medidas de dispersão das médias de pontos na aba BD
B70: Aplicados filtros na aba Mapa de Valor
B71: 44869
B72: Novas ligas adicionadas (Européias inferiores)
B73: 44846
B74: Melhorias na aba CS - Previsões de mercados pelo Poisson
B75: 44791
B76: Ajustes no botão atualizar do dashboard
B77: Inserido dados de custo do gol na aba BD
B78: Inserido medidas de dispersão do custo do gol na aba BD
B79: Inserido probabilidades de match odds na aba BD
B80: Inserido Juice dos jogos na aba BD
B81: Adicionado Mapa de Valor para análise de tabela dinâmica
B82: 44770
B83: Ajustes botão "Atualizar" do dashboard
B84: Inserido dados de dispersão do peso do gol na aba BD
B85: 44697
B86: Inseridos botões para copiar esperança de gols do dashboard para aba CS
B87: 44696
B88: Melhorias na aba FT/HT
B89: 44674
B90: Melhorias nos filtros do dashboard
...

Sheet DASH
C1: BRASIL1 | D1: =A53 -> Athletico-PR | E1: =A82 -> Athletico-PR | F1: Empate | H1: Juice MO %
C2: Odds Bokkie | D2: 3.4 | E2: 2.4 | F2: 3.3 | G2: Big | H2: =(100/D2)+(100/E2)+(100/F2)-100 -> 1.3814617
C3: Odds Justas | D3: =IFERROR(1/((A29+B33)/2),"N/D") -> 2.0172414 | E3: =IFERROR(1/((B29+A33)/2),"N/D") -> 4.1785714 | F3: =IFERROR(1/((A31+B31)/2),"N/D") -> 3.7741935 | G3: Data | H3: 100
C4: Valor das Odds | D4: =IFERROR((D2/D3)-1,"N/D") -> 0.68547009 | E4: =IFERROR((E2/E3)-1,"N/D") -> -0.42564103 | F4: =IFERROR((F2/F3)-1,"N/D") -> -0.12564103 | G4: Bet | H4: =-H2 -> -1.3814617
C5: Amostra | D5: =SUMIF(A53:A73,A53,P53:P73) -> 6 | E5: =SUMIF(A82:A102,A82,Q82:Q102) -> 6 | F5: Amostra total | G5: =D5+E5 -> 12
C6: GOLS FT | D6: CASA | E6: VISITANTE | F6: TT JOGO | G6: Tendências | H6: do Mercado
C7: Gols AVG FT | D7: =(A35+B37)/2 -> 1.5726496 | E7: =(B35+A37)/2 -> 1.0512821 | F7: =D7+E7 -> 2.6239316 | G7: Odd Méd Casa | H7: =GETPIVOTDATA("Média de ODDC",$A$52) -> 2.2068376
C8: Conf DP | D8: =((C29+D31)/2)-((C35+D37)/2) -> 0.059331329 | E8: =((D29+C31)/2)-((D35+C37)/2) -> 0.10748306 | F8: =(D8+E8)/2 -> 0.083407193 | G8: Odd Méd Vis | H8: =GETPIVOTDATA("Média de ODDV",$A$81) -> 4.2301709
C9: Conf CV | D9: =((E29+F31)/2)-((E35+F37)/2) -> 0.011417668 | E9: =((F29+E31)/2)-((F35+E37)/2) -> -0.013193754 | F9: =(D9+E9)/2 -> -0.00088804299 | G9: Odd Méd Emp | H9: =(GETPIVOTDATA("Média de ODDE",$A$52)+GETPIVOTDATA("Média de ODDE",$A$81))/2 -> 3.4776068
C10: Conf AVG | D10: =(D8+D9)/2 -> 0.035374498 | E10: =(E8+E9)/2 -> 0.047144652 | F10: =(F8+F9)/2 -> 0.041259575 | I10: ROI
C11: Over 0,5 FT % | D11: =GETPIVOTDATA("Média de 0,5FT",$A$52) -> 0.94871795 | E11: =GETPIVOTDATA("Média de 0,5FT",$A$81) -> 0.94871795 | F11: =((D11*D5)+(E11*E5))/(G5*2)*2 -> 0.94871795 | G11: Back Casa | H11: =G31 -> -1.84 | I11: =H11/GETPIVOTDATA("Contagem de FAVC",$A$52) -> -0.0044552058
C12: Over 1,5 FT % | D12: =GETPIVOTDATA("Média de 1,5FT",$A$52) -> 0.77777778 | E12: =GETPIVOTDATA("Média de 1,5FT",$A$81) -> 0.77777778 | F12: =((D12*D5)+(E12*E5))/(G5*2)*2 -> 0.77777778 | G12: Back Visitante | H12: =GETPIVOTDATA("Soma de PLBACKV",$A$81) -> -19.85 | I12: =H12/GETPIVOTDATA("Contagem de FAVV",$A$81) -> -0.048062954
C13: Over 2,5 FT % | D13: =GETPIVOTDATA("Média de 2,5FT",$A$52) -> 0.47863248 | E13: =GETPIVOTDATA("Média de 2,5FT",$A$81) -> 0.47863248 | F13: =((D13*D5)+(E13*E5))/(G5*2)*2 -> 0.47863248 | G13: Back Empate | H13: =(G33+G35)/2 -> -12.7 | I13: =H13/((GETPIVOTDATA("Contagem de FAVC",$A$52)+GETPIVOTDATA("Contagem de FAVV",$A$81))/2) -> -0.030750605
C14: Over 3,5 FT % | D14: =GETPIVOTDATA("Média de 3,5FT",$A$52) -> 0.21367521 | E14: =GETPIVOTDATA("Média de 3,5FT",$A$81) -> 0.21367521 | F14: =((D14*D5)+(E14*E5))/(G5*2)*2 -> 0.21367521 | G14: Odd justa Over/Ambas
C15: Ambas Marcam | D15: =GETPIVOTDATA("Média de AMBFT",$A$52) -> 0.56410256 | E15: =GETPIVOTDATA("Média de AMBFT",$A$81) -> 0.56410256 | F15: =((D15*D5)+(E15*E5))/(G5*2)*2 -> 0.56410256 | G15: Ambas Marcam | H15: =1/((D15+E15)/2) -> 1.7727273 | I15: VOL TOTAL
C16: Goleada Casa | D16: =GETPIVOTDATA("Média de GOLEAC",$A$52) -> 0.068376068 | E16: =GETPIVOTDATA("Média de GOLEAC",$A$81) -> 0.068376068 | F16: =((D16*D5)+(E16*E5))/(G5*2)*2 -> 0.068376068 | G16: Over 1,5 FT | H16: =1/((D12+E12)/2) -> 1.2857143 | I16: =COUNT(BDBRA1!D2:D1094) -> 117
C17: Goleada Visit | D17: =GETPIVOTDATA("Média de GOLEAV",$A$52) -> 0.017094017 | E17: =GETPIVOTDATA("Média de GOLEAV",$A$81) -> 0.017094017 | F17: =((D17*D5)+(E17*E5))/(G5*2)*2 -> 0.017094017 | G17: Over 2,5 FT | H17: =1/((D13+E13)/2) -> 2.0892857
F18: MÉDIA LIGA
C19: Média Pts | D19: =GETPIVOTDATA("Média de PTC",$A$52) -> 1.7521368 | E19: =GETPIVOTDATA("Média de PTV",$A$81) -> 0.98290598 | F19: =(BDBRA1!AR22+BDBRA1!AS22)/2 -> 1.3746429
C20: Peso Pts | D20: =GETPIVOTDATA("Média de PESOPTC",$A$52) -> 3.5661538 | E20: =GETPIVOTDATA("Média de PESOPTV",$A$81) -> 3.4850427 | F20: =(BDBRA1!DJ22+BDBRA1!DK22)/2 -> 3.763358
C21: Peso Gol | D21: =GETPIVOTDATA("Média de GC/ODDV",$A$52) -> 0.41567658 | E21: =GETPIVOTDATA("Média de GV/ODDC",$A$81) -> 0.4771479 | F21: =(BDBRA1!CV22+BDBRA1!CW22)/2 -> 0.44901813
C22: Custo Gol | D22: =GETPIVOTDATA("Média de CustGC",$A$52) -> 0.44215449 | E22: =GETPIVOTDATA("Média de CustGV",$A$81) -> 0.47176409 | F22: =(Tabela2[[#This Row],[CUSTGC]]+Tabela2[[#This Row],[CUSTGV]])/2 -> 0.45374418
A28: MED VIT CASA | B28: MED VIT VIS | C28: DP GOLS CASA | D28: DP GOLS VIS | E28: CV GOLS CASA | F28: CV GOLS VIS
A29: =GETPIVOTDATA("Média de VITC",$A$52) -> 0.4957265 | B29: =GETPIVOTDATA("Média de VITV",$A$81) -> 0.23931624 | C29: =GETPIVOTDATA("DesvPad de FTHG2",$A$52) -> 1.1470821 | D29: =GETPIVOTDATA("DesvPad de FTAG2",$A$81) -> 0.95453684 | E29: =C29/A35 -> 0.72939456 | F29: =IFERROR(D29/B35,0) -> 0.90797407
A30: MED EMP CASA | B30: MED EMP VIS | C30: DP GS CASA | D30: DP GS VIS | E30: CV GS CASA | F30: CV GS VIS | G30: PL BACK CASA
A31: =GETPIVOTDATA("Média de EMP",$A$52) -> 0.26495726 | B31: =GETPIVOTDATA("Média de EMP",$A$81) -> 0.26495726 | C31: =GETPIVOTDATA("DesvPad de FTAG2",$A$52) -> 0.95453684 | D31: =GETPIVOTDATA("DesvPad de FTHG2",$A$81) -> 1.1470821 | E31: =C31/A37 -> 0.90797407 | F31: =D31/B37 -> 0.72939456 | G31: =GETPIVOTDATA("Soma de PLBACKC",$A$52) -> -1.84
A32: MED DERR CASA | B32: MED DERR VIS | C32: DP AVG G CASA | D32: DP AVG G VIS | E32: CV AVG G CASA | F32: CV AVG G VIS | G32: PL EMP CASA
A33: =GETPIVOTDATA("Média de VITV",$A$52) -> 0.23931624 | B33: =GETPIVOTDATA("Média de VITC",$A$81) -> 0.4957265 | C33: =(C29+D31)/2 -> 1.1470821 | D33: =(D29+C31)/2 -> 0.95453684 | E33: =(E29+F31)/2 -> 0.72939456 | F33: =(F29+E31)/2 -> 0.90797407 | G33: =GETPIVOTDATA("Soma de PLEMP",$A$52) -> -12.7
A34: MED GOLS CASA | B34: MEDIA GOLS VIS | C34: DPMGLIG CASA | D34: DPGMGLIG VIS | E34: CVMGLIG CASA | F34: CVMGLIG VIS | G34: PL EMPVIS
A35: =GETPIVOTDATA("Média de FTHG",$A$52) -> 1.5726496 | B35: =GETPIVOTDATA("Média de FTAG",$A$81) -> 1.0512821 | C35: =BDBRA1!BF22 -> 1.1358432 | D35: =BDBRA1!BG22 -> 0.8257766 | E35: =BDBRA1!BH22 -> 0.75832866 | F35: =BDBRA1!BI22 -> 0.90638264 | G35: =GETPIVOTDATA("Soma de PLEMP",$A$81) -> -12.7
A36: MED GS CASA | B36: MED GS VIS | C36: DPMGSLIG CASA | D36: DPMGSLIG VIS | E36: CVMGSLIG CASA | F36: CVMGSLIG VIS | G36: PL BACK VIS
A37: =GETPIVOTDATA("Média de FTAG",$A$52) -> 1.0512821 | B37: =GETPIVOTDATA("Média de FTHG",$A$81) -> 1.5726496 | C37: =BDBRA1!BM22 -> 0.86833097 | D37: =BDBRA1!BN22 -> 1.0396583 | E37: =BDBRA1!BO22 -> 0.93595301 | F37: =BDBRA1!BP22 -> 0.67762514 | G37: =GETPIVOTDATA("Soma de PLBACKV",$A$81) -> -19.85
A52: Rótulos de Linha | B52: Média de ODDC | C52: Média de ODDE | D52: Média de ODDV | E52: Soma de SLDC | F52: Soma de SLDV | G52: Soma de PLBACKC | H52: Soma de PLBACKV | I52: Média de GOLEAC | J52: Média de GOLEAV | K52: Média de AMBFT | L52: Contagem de CONTAG | M52: Média de VITC | N52: Média de EMP | O52: Média de VITV | P52: Contagem de FAVC | Q52: Contagem de FAVV | R52: Média de FTHG | S52: Média de FTAG | T52: DesvPad de FTHG2 | U52: DesvPad de FTAG2 | V52: Soma de PLEMP | W52: Média de 0,5FT | X52: Média de 1,5FT | Y52: Média de 2,5FT | Z52: Média de 3,5FT | AA52: Média de GC/ODDV | AB52: Média de PTC | AC52: Média de PESOPTC | AD52: Média de CustGC
A53: Athletico-PR | B53: 1.9733333 | C53: 3.325 | D53: 4.1416667 | E53: 8 | F53: -8 | G53: 3.27 | H53: -3.15 | I53: 0.16666667 | J53: 0 | K53: 0.5 | L53: 6 | M53: 0.83333333 | N53: 0 | O53: 0.16666667 | P53: 6 | Q53: 6 | R53: 2 | S53: 0.66666667 | T53: 1.2649111 | U53: 0.51639778 | V53: -6 | W53: 1 | X53: 0.83333333 | Y53: 0.5 | Z53: 0.16666667 | AA53: 0.47501255 | AB53: 2.5 | AC53: 4.635 | AD53: 0.37426328
A54: Atletico-MG | B54: 2.164 | C54: 3.44 | D54: 4.08 | E54: 3 | F54: -3 | G54: 1.41 | H54: -5 | I54: 0 | J54: 0 | K54: 0.6 | L54: 5 | M54: 0.6 | N54: 0.4 | O54: 0 | P54: 5 | Q54: 5 | R54: 1.8 | S54: 1.2 | T54: 0.83666003 | U54: 1.3038405 | V54: 2.6 | W54: 1 | X54: 0.6 | Y54: 0.6 | Z54: 0.4 | AA54: 0.4740897 | AB54: 2.2 | AC54: 4.728 | AD54: 0.31469271
A55: Bahia | B55: 1.908 | C55: 3.46 | D55: 4.34 | E55: 4 | F55: -4 | G55: -1.63 | H55: -2.15 | I55: 0 | J55: 0 | K55: 0.6 | L55: 5 | M55: 0.4 | N55: 0.4 | O55: 0.2 | P55: 5 | Q55: 5 | R55: 1.6 | S55: 0.8 | T55: 0.89442719 | U55: 0.83666003 | V55: 1.9 | W55: 1 | X55: 1 | Y55: 0.4 | Z55: 0 | AA55: 0.3663325 | AB55: 1.6 | AC55: 2.756 | AD55: 0.39921173
A56: Botafogo RJ | B56: 2.645 | C56: 3.25 | D56: 3.1275 | E56: 2 | F56: -2 | G56: 0.62 | H56: -2.09 | I56: 0.25 | J56: 0 | K56: 0.5 | L56: 4 | M56: 0.5 | N56: 0.25 | O56: 0.25 | P56: 4 | Q56: 4 | R56: 2.25 | S56: 1.75 | T56: 1.7078251 | U56: 1.2583057 | V56: -0.6 | W56: 1 | X56: 1 | Y56: 1 | Z56: 0.75 | AA56: 0.66316527 | AB56: 1.75 | AC56: 3.93 | AD56: 0.38029775
A57: Bragantino | B57: 2.2533333 | C57: 3.35 | D57: 3.975 | E57: 4 | F57: -4 | G57: 1.3 | H57: 1.4 | I57: 0.16666667 | J57: 0 | K57: 0.66666667 | L57: 6 | M57: 0.5 | N57: 0.16666667 | O57: 0.33333333 | P57: 6 | Q57: 6 | R57: 1.8333333 | S57: 1.1666667 | T57: 1.3291601 | U57: 0.98319208 | V57: -2.7 | W57: 1 | X57: 0.83333333 | Y57: 0.66666667 | Z57: 0.16666667 | AA57: 0.52263412 | AB57: 1.6666667 | AC57: 3.985 | AD57: 0.36894929
A58: Chapecoense-SC | B58: 3.0785714 | C58: 3.2571429 | D58: 2.3728571 | E58: -5 | F58: 5 | G58: -4 | H58: -2.84 | I58: 0.14285714 | J58: 0.28571429 | K58: 0.71428571 | L58: 7 | M58: 0.14285714 | N58: 0.57142857 | O58: 0.28571429 | P58: 7 | Q58: 7 | R58: 1.4285714 | S58: 2.1428571 | T58: 1.5118579 | U58: 1.5735916 | V58: 5.9 | W58: 0.85714286 | X58: 0.85714286 | Y58: 0.57142857 | Z58: 0.57142857 | AA58: 0.57724265 | AB58: 1 | AC58: 2.9214286 | AD58: 0.46113394
A59: Corinthians | B59: 2.305 | C59: 3.2583333 | D59: 3.625 | E59: -2 | F59: 2 | G59: -4.14 | H59: 5.9 | I59: 0 | J59: 0 | K59: 0.33333333 | L59: 6 | M59: 0.16666667 | N59: 0.33333333 | O59: 0.5 | P59: 6 | Q59: 6 | R59: 0.66666667 | S59: 1 | T59: 0.81649658 | U59: 0.89442719 | V59: 0.1 | W59: 0.83333333 | X59: 0.66666667 | Y59: 0.16666667 | Z59: 0 | AA59: 0.19633285 | AB59: 0.83333333 | AC59: 1.9383333 | AD59: 0.66958005
...

Sheet FT
A1: Rótulos de Linha | B1: Soma de FTHG | C1: Soma de FTAG
A2: 3 | B2: 0 | C2: 1
A3: Internacional | B3: 0 | C3: 1
A4: Athletico-PR | B4: 0 | C4: 1
A5: 3.9 | B5: 0 | C5: 1
A6: 1.96 | B6: 0 | C6: 1
A7: 46050 | B7: 0 | C7: 1
A8: 4 | B8: 2 | C8: 0
A9: Vitoria | B9: 2 | C9: 0
A10: Remo | B10: 2 | C10: 0
A11: 4.75 | B11: 2 | C11: 0
A12: 1.79 | B12: 2 | C12: 0
A13: 46050 | B13: 2 | C13: 0
A14: 5 | B14: 2 | C14: 1
A15: Fluminense | B15: 2 | C15: 1
A16: Gremio | B16: 2 | C16: 1
A17: 6 | B17: 2 | C17: 1
A18: 1.53 | B18: 2 | C18: 1
A19: 46050 | B19: 2 | C19: 1
A20: 9 | B20: 2 | C20: 1
A21: Mirassol | B21: 2 | C21: 1
A22: Vasco | B22: 2 | C22: 1
A23: 4.5 | B23: 2 | C23: 1
A24: 1.79 | B24: 2 | C24: 1
A25: 46051 | B25: 2 | C25: 1
A26: 12 | B26: 1 | C26: 1
A27: Flamengo RJ | B27: 1 | C27: 1
A28: Internacional | B28: 1 | C28: 1
A29: 7.5 | B29: 1 | C29: 1
A30: 1.41 | B30: 1 | C30: 1
A31: 46057 | B31: 1 | C31: 1
A32: 16 | B32: 5 | C32: 1
A33: Palmeiras | B33: 5 | C33: 1
A34: Vitoria | B34: 5 | C34: 1
A35: 10 | B35: 5 | C35: 1
A36: 1.3 | B36: 5 | C36: 1
A37: 46058 | B37: 5 | C37: 1
A38: 18 | B38: 1 | C38: 1
A39: Vasco | B39: 1 | C39: 1
A40: Chapecoense-SC | B40: 1 | C40: 1
...

Sheet CS
E1: CASA | F1: VISIT | N1: oddj | O1: oddmerc | P1: EV
B2: Gols Casa | C2: =DASH!D7 -> 1.5726496 | E2: =T27 -> (vazio) | F2: =T58 -> (vazio) | G2: CASA | H2: =SUM(B16:B25,C17:C25,D18:D25,E19:E25,F20:F25,G21:G25,H22:H25,I23:I25,J24:J25,K25) -> 0.49423214 | I2: =1/H2 -> 2.0233407 | J2: OVER 0,5 | K2: =SUM(C15:L25,B16:B25) -> 0.92748192 | L2: =1/K2 -> 1.0781881 | M2: 0x0 | N2: =1/B15 -> 13.789834 | O2: 14.5 | P2: =((1/N2)*(O2-1))-(1-(1/N2)) -> 0.051499274
B3: Gol Vis | C3: =DASH!E7 -> 1.0512821 | D3: 0 | E3: =_xlfn.POISSON.DIST(0,C2,FALSE) -> 0.20749468 | F3: =_xlfn.POISSON.DIST(0,C3,FALSE) -> 0.3494894 | G3: EMPATE | H3: =SUM(B15,C16,D17,E18,F19,G20,H21,I22,J23,K24,L25) -> 0.25207323 | I3: =1/H3 -> 3.9671011 | J3: OVER 1,5 | K3: =SUM(D15:L25,C16:C25,B17:B25) -> 0.73720177 | L3: =1/K3 -> 1.3564807 | M3: 0X1 | N3: =1/C15 -> 13.117159 | O3: 17.8 | P3: =((1/N3)*(O3-1))-(1-(1/N3)) -> 0.35700118
B4: Fç At Casa | C4: =VLOOKUP(E2,BDBRA1!BQ1:BW22,2,FALSE) -> #N/A | D4: 1 | E4: =_xlfn.POISSON.DIST(1,C2,FALSE) -> 0.32631642 | F4: =_xlfn.POISSON.DIST(1,C3,FALSE) -> 0.36741193 | G4: VISIT | H4: =SUM(C15:L15,D16:L16,E17:L17,F18:L18,G19:L19,H20:L20,I21:L21,J22:L22,K23:L23,L24) -> 0.25369374 | I4: =1/H4 -> 3.9417607 | J4: OVER 2,5 | K4: =SUM(E15:L25,D16:D25,C17:C25,B18:B25) -> 0.48756072 | L4: =1/K4 -> 2.0510266 | M4: 0X2 | N4: =1/D15 -> 24.954595 | O4: 37.5 | P4: =((1/N4)*(O4-1))-(1-(1/N4)) -> 0.50272927
B5: Fç Df Casa | C5: =VLOOKUP(E2,BDBRA1!BQ1:BW22,4,FALSE) -> #N/A | D5: 2 | E5: =_xlfn.POISSON.DIST(2,C2,FALSE) -> 0.25659069 | F5: =_xlfn.POISSON.DIST(2,C3,FALSE) -> 0.19312678 | G5: GOLE CAS | H5: =SUM(B19:E25,F20:F25,G21:G25,H22:H25,I23:I25,J24:J25,K25) -> 0.073830763 | I5: =1/H5 -> 13.54449 | J5: OVER 3,5 | K5: =SUM(F15:L25,E16:E25,D17:D25,C18:C25,B19:B25) -> 0.2692137 | L5: =1/K5 -> 3.7145212 | M5: 0X3 | N5: =1/E15 -> 71.211892 | O5: 110 | P5: =((1/N5)*(O5-1))-(1-(1/N5)) -> 0.54468582
B6: Fç At Vis | C6: =VLOOKUP(F2,BDBRA1!BQ1:BW22,3,FALSE) -> #N/A | D6: 3 | E6: =_xlfn.POISSON.DIST(3,C2,FALSE) -> 0.13450908 | F6: =_xlfn.POISSON.DIST(3,C3,FALSE) -> 0.067676907 | G6: GOLE VIS | H6: =SUM(F15:L18,G19:L19,H20:L20,I21:L21,J22:L22,K23:L23,L24) -> 0.020872544 | I6: =1/H6 -> 47.909829 | J6: OVER 4,5 | K6: =SUM(G15:L25,F16:F25,E17:E25,D18:D25,C19:C25,B20:B25) -> 0.12598179 | L6: =1/K6 -> 7.9376552 | M6: 1X0 | N6: =1/B16 -> 8.7685355 | O6: 8.5 | P6: =((1/N6)*(O6-1))-(1-(1/N6)) -> -0.030624896
B7: Fç Df Vis | C7: =VLOOKUP(F2,BDBRA1!BQ1:BW22,5,FALSE) -> #N/A | D7: 4 | E7: =_xlfn.POISSON.DIST(4,C2,FALSE) -> 0.052883912 | F7: =_xlfn.POISSON.DIST(4,C3,FALSE) -> 0.01778688 | G7: BTTS | H7: =SUM(C16:L25) -> 0.51553253 | I7: =1/H7 -> 1.9397418 | J7: OVER 5,5 | K7: =SUM(H15:L25,G16:G25,F17:F25,E18:E25,D19:D25,C20:C25,B21:B25) -> 0.05081564 | L7: =1/K7 -> 19.678981 | M7: 1X1 | N7: =1/C16 -> 8.340802 | O7: 8.3 | P7: =((1/N7)*(O7-1))-(1-(1/N7)) -> -0.0048918614
D8: 5 | E8: =_xlfn.POISSON.DIST(5,C2,FALSE) -> 0.016633572 | F8: =_xlfn.POISSON.DIST(5,C3,FALSE) -> 0.0037398054 | G8: BTTS NÃO | H8: =SUM(B15:L15,B16:B25) -> 0.48446658 | I8: =1/H8 -> 2.0641259 | J8: OVER 6,5 | K8: =SUM(I15:L25,H16:H25,G17:G25,F18:F25,E19:E25,D20:D25,C21:C25,B22:B25) -> 0.017943834 | L8: =1/K8 -> 55.72945 | M8: 1X2 | N8: =1/D16 -> 15.867867 | O8: 18.7 | P8: =((1/N8)*(O8-1))-(1-(1/N8)) -> 0.17848225
D9: 6 | E9: =_xlfn.POISSON.DIST(6,C2,FALSE) -> 0.0043597967 | F9: =_xlfn.POISSON.DIST(6,C3,FALSE) -> 0.00065526506 | M9: 1X3 | N9: =1/E16 -> 45.281475 | O9: 59 | P9: =((1/N9)*(O9-1))-(1-(1/N9)) -> 0.30296109
D10: 7 | E10: =_xlfn.POISSON.DIST(7,C2,FALSE) -> 0.00097949035 | F10: =_xlfn.POISSON.DIST(7,C3,FALSE) -> 9.840977e-05 | M10: 2X0 | N10: =1/B17 -> 11.15129 | O10: 9.5 | P10: =((1/N10)*(O10-1))-(1-(1/N10)) -> -0.1480806
D11: 8 | E11: =_xlfn.POISSON.DIST(8,C2,FALSE) -> 0.00019254938 | F11: =_xlfn.POISSON.DIST(8,C3,FALSE) -> 1.2932053e-05 | M11: 2X1 | N11: =1/C17 -> 10.607324 | O11: 9.1 | P11: =((1/N11)*(O11-1))-(1-(1/N11)) -> -0.14210222
D12: 9 | E12: =_xlfn.POISSON.DIST(9,C2,FALSE) -> 3.3645856e-05 | F12: =_xlfn.POISSON.DIST(9,C3,FALSE) -> 1.5105817e-06 | M12: 2X2 | N12: =1/D17 -> 20.179788 | O12: 18.2 | P12: =((1/N12)*(O12-1))-(1-(1/N12)) -> -0.098107463
D13: 10 | E13: =_xlfn.POISSON.DIST(10,C2,FALSE) -> 5.2913142e-06 | F13: =_xlfn.POISSON.DIST(10,C3,FALSE) -> 1.5880474e-07 | M13: 2X3 | N13: =1/E17 -> 57.586224 | O13: 59 | P13: =((1/N13)*(O13-1))-(1-(1/N13)) -> 0.0245506
B14: 0 | C14: 1 | D14: 2 | E14: 3 | F14: 4 | G14: 5 | H14: 6 | I14: 7 | J14: 8 | K14: 9 | L14: 10 | M14: 3X0 | N14: =1/B18 -> 21.272297 | O14: 16.2 | P14: =((1/N14)*(O14-1))-(1-(1/N14)) -> -0.23844614
A15: 0 | B15: =E3*F3 -> 0.072517191 | C15: =E3*F4 -> 0.076236022 | D15: =E3*F5 -> 0.040072781 | E15: =E3*F6 -> 0.014042598 | F15: =E3*F7 -> 0.0036906829 | G15: =E3*F8 -> 0.00077598974 | H15: =E3*F9 -> 0.00013596401 | I15: =E3*F10 -> 2.0419504e-05 | J15: =E3*F11 -> 2.6833322e-06 | K15: =E3*F12 -> 3.1343767e-07 | L15: =E3*F13 -> 3.295114e-08 | M15: 3X1 | N15: =1/C18 -> 20.234624 | O15: 16.2 | P15: =((1/N15)*(O15-1))-(1-(1/N15)) -> -0.1993921
A16: 1 | B16: =E4*F3 -> 0.11404413 | C16: =E4*F4 -> 0.11989255 | D16: =E4*F5 -> 0.063020441 | E16: =E4*F6 -> 0.022084086 | F16: =E4*F7 -> 0.0058041509 | G16: =E4*F8 -> 0.0012203599 | H16: =E4*F9 -> 0.00021382375 | I16: =E4*F10 -> 3.2112724e-05 | J16: =E4*F11 -> 4.2199413e-06 | K16: =E4*F12 -> 4.9292762e-07 | L16: =E4*F13 -> 5.1820596e-08 | M16: 3X2 | N16: =1/D18 -> 38.495139 | O16: 31.5 | P16: =((1/N16)*(O16-1))-(1-(1/N16)) -> -0.18171486
A17: 2 | B17: =E5*F3 -> 0.089675726 | C17: =E5*F4 -> 0.094274481 | D17: =E5*F5 -> 0.049554535 | E17: =E5*F6 -> 0.017365264 | F17: =E5*F7 -> 0.0045639477 | G17: =E5*F8 -> 0.00095959926 | H17: =E5*F9 -> 0.00016813491 | I17: =E5*F10 -> 2.5251031e-05 | J17: =E5*F11 -> 3.3182444e-06 | K17: =E5*F12 -> 3.876012e-07 | L17: =E5*F13 -> 4.0747819e-08 | M17: 3x3 | N17: =1/E18 -> 109.85198 | O17: 94 | P17: =((1/N17)*(O17-1))-(1-(1/N17)) -> -0.1443031
A18: 3 | B18: =E6*F3 -> 0.047009497 | C18: =E6*F4 -> 0.049420241 | D18: =E6*F5 -> 0.025977306 | E18: =E6*F6 -> 0.0091031586 | F18: =E6*F7 -> 0.0023924968 | G18: =E6*F8 -> 0.00050303779 | H18: =E6*F9 -> 8.81391e-05 | I18: =E6*F10 -> 1.3237008e-05 | J18: =E6*F11 -> 1.7394786e-06 | K18: =E6*F12 -> 2.0318696e-07 | L18: =E6*F13 -> 2.136068e-08 | M18: GOLE CAS | N18: =I5 -> 13.54449 | O18: 22 | P18: =((1/N18)*(O18-1))-(1-(1/N18)) -> 0.62427679
A19: 4 | B19: =E7*F3 -> 0.018482367 | C19: =E7*F4 -> 0.01943018 | D19: =E7*F5 -> 0.0102133 | E19: =E7*F6 -> 0.0035790196 | F19: =E7*F7 -> 0.00094063977 | G19: =E7*F8 -> 0.00019777554 | H19: =E7*F9 -> 3.4652979e-05 | I19: =E7*F10 -> 5.2042936e-06 | J19: =E7*F11 -> 6.8389756e-07 | K19: =E7*F12 -> 7.988547e-08 | L19: =E7*F13 -> 8.398216e-09 | M19: GOLE VIS | N19: =I6 -> 47.909829 | O19: 33 | P19: =((1/N19)*(O19-1))-(1-(1/N19)) -> -0.31120606
A20: 5 | B20: =E8*F3 -> 0.0058132572 | C20: =E8*F4 -> 0.0061113729 | D20: =E8*F5 -> 0.0032123883 | E20: =E8*F6 -> 0.0011257087 | F20: =E8*F7 -> 0.00029585935 | G20: =E8*F8 -> 6.2206324e-05 | H20: =E8*F9 -> 1.0899399e-05 | I20: =E8*F10 -> 1.636906e-06 | J20: =E8*F11 -> 2.1510624e-07 | K20: =E8*F12 -> 2.512637e-08 | L20: =E8*F13 -> 2.6414902e-09 | M20: OUTR EMP | N20: =1/SUM(F19,G20,H21,I22,J23,K24,L25) -> 994.23162 | O20: 55 | P20: =((1/N20)*(O20-1))-(1-(1/N20)) -> -0.9446809
A21: 6 | B21: =E9*F3 -> 0.0015237027 | C21: =E9*F4 -> 0.0016018413 | D21: =E9*F5 -> 0.00084199352 | E21: =E9*F6 -> 0.00029505756 | F21: =E9*F7 -> 7.7547179e-05 | G21: =E9*F8 -> 1.6304791e-05 | H21: =E9*F9 -> 2.8568224e-06 | I21: =E9*F10 -> 4.2904659e-07 | J21: =E9*F11 -> 5.6381123e-08 | K21: =E9*F12 -> 6.5858292e-09 | L21: =E9*F13 -> 6.923564e-10
A22: 7 | B22: =E10*F3 -> 0.00034232149 | C22: =E10*F4 -> 0.00035987644 | D22: =E10*F5 -> 0.00018916582 | E22: =E10*F6 -> 6.6288878e-05 | F22: =E10*F7 -> 1.7422077e-05 | G22: =E10*F8 -> 3.6631033e-06 | H22: =E10*F9 -> 6.418258e-07 | I22: =E10*F10 -> 9.639142e-08 | J22: =E10*F11 -> 1.2666821e-08 | K22: =E10*F12 -> 1.4796002e-09 | L22: =E10*F13 -> 1.5554771e-10
A23: 8 | B23: =E11*F3 -> 6.7293969e-05 | C23: =E11*F4 -> 7.0744941e-05 | D23: =E11*F5 -> 3.7186444e-05 | E23: =E11*F6 -> 1.3031147e-05 | F23: =E11*F7 -> 3.4248527e-06 | G23: =E11*F8 -> 7.2009724e-07 | H23: =E11*F9 -> 1.2617088e-07 | I23: =E11*F10 -> 1.8948741e-08 | J23: =E11*F11 -> 2.4900589e-09 | K23: =E11*F12 -> 2.9086158e-10 | L23: =E11*F13 -> 3.0577756e-11
A24: 9 | B24: =E12*F3 -> 1.175887e-05 | C24: =E12*F4 -> 1.2361889e-05 | D24: =E12*F5 -> 6.4979161e-06 | E24: =E12*F6 -> 2.2770475e-06 | F24: =E12*F7 -> 5.9845479e-07 | G24: =E12*F8 -> 1.2582896e-07 | H24: =E12*F9 -> 2.2046954e-08 | I24: =E12*F10 -> 3.311081e-09 | J24: =E12*F11 -> 4.3511e-10 | K24: =E12*F12 -> 5.0824815e-11 | L24: =E12*F13 -> 5.3431216e-12
A25: 10 | B25: =E13*F3 -> 1.8492582e-06 | C25: =E13*F4 -> 1.944092e-06 | D25: =E13*F5 -> 1.0218945e-06 | E25: =E13*F6 -> 3.5809978e-07 | F25: =E13*F7 -> 9.4115968e-08 | G25: =E13*F8 -> 1.9788486e-08 | H25: =E13*F9 -> 3.4672133e-09 | I25: =E13*F10 -> 5.2071701e-10 | J25: =E13*F11 -> 6.8427556e-11 | K25: =E13*F12 -> 7.9929624e-12 | L25: =E13*F13 -> 8.4028579e-13 | N25: HANDICAPS
T26: Rótulos de Linha | U26: Contagem de FAVC
G27: HANDICAPS | T27: (vazio) | U27: 296
T28: Fluminense | U28: 6
B29: CASA | C29: FULL | D29: ASIAN | F29: VISITANTE | G29: FULL | H29: ASIAN | J29: OVER | K29: FULL | L29: ASIAN | T29: Bahia | U29: 5
B30: -2.5 | C30: =SUM(B20:D20,B19:C19,B18) -> 0.10005906 | F30: -2.5 | G30: =SUM(E15:G15,F16:G16,G17) -> 0.026493381 | J30: 5.5 | K30: =SUM(H15:L25,G16:G25,F17:F25,E18:E25,D19:D25,C20:C25,B21:B25) -> 0.05081564 | T30: Athletico-PR | U30: 6
B31: -2.25 | C31: =SUM(B20:D20,B19:C19,B18) -> 0.10005906 | D31: =SUM(B17,C18,D19,E20) -> 0.15043498 | E31: -0.5 | F31: -2.25 | G31: =SUM(E15:G15,F16:G16,G17) -> 0.026493381 | H31: =SUM(D15,E16,F17,G18) -> 0.067223852 | I31: -0.5 | J31: 5.25 | K31: =SUM(H15:L25,G16:G25,F17:F25,E18:E25,D19:D25,C20:C25,B21:B25) -> 0.05081564 | L31: =SUM(G15,F16,E17,D18,C19,B20) -> 0.075166148 | M31: -0.5 | T31: Chapecoense-SC | U31: 7
B32: -2 | C32: =SUM(B20:D20,B19:C19,B18) -> 0.10005906 | D32: =SUM(B17,C18,D19,E20) -> 0.15043498 | E32: 0 | F32: -2 | G32: =SUM(E15:G15,F16:G16,G17) -> 0.026493381 | H32: =SUM(D15,E16,F17,G18) -> 0.067223852 | I32: 0 | J32: 5 | K32: =SUM(H15:L25,G16:G25,F17:F25,E18:E25,D19:D25,C20:C25,B21:B25) -> 0.05081564 | L32: =SUM(G15,F16,E17,D18,C19,B20) -> 0.075166148 | M32: 0 | T32: Corinthians | U32: 6
B33: -1.75 | C33: =SUM(B20:D20,B19:C19,B18) -> 0.10005906 | D33: =SUM(B17,C18,D19,E20) -> 0.15043498 | E33: 0.5 | F33: -1.75 | G33: =SUM(E15:G15,F16:G16,G17) -> 0.026493381 | H33: =SUM(D15,E16,F17,G18) -> 0.067223852 | I33: 0.5 | J33: 4.75 | K33: =SUM(H15:L25,G16:G25,F17:F25,E18:E25,D19:D25,C20:C25,B21:B25) -> 0.05081564 | L33: =SUM(G15,F16,E17,D18,C19,B20) -> 0.075166148 | M33: 0.5 | T33: Bragantino | U33: 6
B34: -1.5 | C34: =SUM(B17:B20,C18:C20,D19:D20,E20) -> 0.25049404 | F34: -1.5 | G34: =SUM(D15:G15,E16:G16,F17:G17,G18) -> 0.093717233 | J34: 4.5 | K34: =SUM(G15:L25,F16:F25,E17:E25,D18:D25,C19:C25,B20:B25) -> 0.12598179 | T34: Santos | U34: 7
B35: -1.25 | C35: =SUM(B17:B20,C18:C20,D19:D20,E20) -> 0.25049404 | D35: =SUM(B16,C17,D18,E19,F20) -> 0.2381708 | E35: -0.5 | F35: -1.25 | G35: =SUM(D15:G15,E16:G16,F17:G17,G18) -> 0.093717233 | H35: =SUM(C15,D16,E17,F18,G19) -> 0.159212 | I35: -0.5 | J35: 4.25 | K35: =SUM(G15:L25,F16:F25,E17:E25,D18:D25,C19:C25,B20:B25) -> 0.12598179 | L35: =SUM(F15,E16,D17,C18,B19) -> 0.14323191 | M35: -0.5 | T35: Gremio | U35: 5
B36: -1 | C36: =SUM(B17:B20,C18:C20,D19:D20,E20) -> 0.25049404 | D36: =SUM(B16,C17,D18,E19,F20) -> 0.2381708 | E36: 0 | F36: -1 | G36: =SUM(D15:G15,E16:G16,F17:G17,G18) -> 0.093717233 | H36: =SUM(C15,D16,E17,F18,G19) -> 0.159212 | I36: 0 | J36: 4 | K36: =SUM(G15:L25,F16:F25,E17:E25,D18:D25,C19:C25,B20:B25) -> 0.12598179 | L36: =SUM(F15,E16,D17,C18,B19) -> 0.14323191 | M36: 0 | T36: Palmeiras | U36: 6
B37: -0.75 | C37: =SUM(B17:B20,C18:C20,D19:D20,E20) -> 0.25049404 | D37: =SUM(B16,C17,D18,E19,F20) -> 0.2381708 | E37: 0.5 | F37: -0.75 | G37: =SUM(D15:G15,E16:G16,F17:G17,G18) -> 0.093717233 | H37: =SUM(C15,D16,E17,F18,G19) -> 0.159212 | I37: 0.5 | J37: 3.75 | K37: =SUM(G15:L25,F16:F25,E17:E25,D18:D25,C19:C25,B20:B25) -> 0.12598179 | L37: =SUM(F15,E16,D17,C18,B19) -> 0.14323191 | M37: 0.5 | T37: Atletico-MG | U37: 5
A38: BACK | B38: -0.5 | C38: =SUM(B16:B20,C17:C20,D18:D20,E19:E20,F20) -> 0.48866483 | F38: -0.5 | G38: =SUM(C15:G15,D16:G16,E17:G17,F18:G18,G19) -> 0.25292923 | J38: 3.5 | K38: =SUM(F15:L25,E16:E25,D17:D25,C18:C25,B19:B25) -> 0.2692137 | T38: Internacional | U38: 7
B39: -0.25 | C39: =SUM(B16:B20,C17:C20,D18:D20,E19:E20,F20) -> 0.48866483 | D39: =SUM(B15,C16,D17,E18,F19,G20) -> 0.25207028 | E39: -0.5 | F39: -0.25 | G39: =SUM(C15:G15,D16:G16,E17:G17,F18:G18,G19) -> 0.25292923 | H39: =SUM(B15,C16,D17,E18,F19,G20) -> 0.25207028 | I39: -0.5 | J39: 3.25 | K39: =SUM(F15:L25,E16:E25,D17:D25,C18:C25,B19:B25) -> 0.2692137 | L39: =SUM(E15,D16,C17,B18) -> 0.21834702 | M39: -0.5 | T39: Sao Paulo | U39: 5
A40: DNB | B40: 0 | C40: =SUM(B16:B20,C17:C20,D18:D20,E19:E20,F20) -> 0.48866483 | D40: =SUM(B15,C16,D17,E18,F19,G20) -> 0.25207028 | E40: 0 | F40: 0 | G40: =SUM(C15:G15,D16:G16,E17:G17,F18:G18,G19) -> 0.25292923 | H40: =SUM(B15,C16,D17,E18,F19,G20) -> 0.25207028 | I40: 0 | J40: 3 | K40: =SUM(F15:L25,E16:E25,D17:D25,C18:C25,B19:B25) -> 0.2692137 | M40: 0 | T40: Flamengo RJ | U40: 5
...

Sheet EVOL
S1: Rótulos de Linha | T1: Soma de FTHG | U1: Soma de FTAG
S2: 1 | T2: 2 | U2: 2
S3: Atletico-MG | T3: 2 | U3: 2
S4: Palmeiras | T4: 2 | U4: 2
S5: 2 | T5: 0 | U5: 1
S6: Coritiba | T6: 0 | U6: 1
S7: Bragantino | T7: 0 | U7: 1
S8: 3 | T8: 0 | U8: 1
S9: Internacional | T9: 0 | U9: 1
S10: Athletico-PR | T10: 0 | U10: 1
S11: 4 | T11: 2 | U11: 0
S12: Vitoria | T12: 2 | U12: 0
S13: Remo | T13: 2 | U13: 0
S14: 5 | T14: 2 | U14: 1
S15: Fluminense | T15: 2 | U15: 1
S16: Gremio | T16: 2 | U16: 1
S17: 6 | T17: 4 | U17: 2
S18: Chapecoense-SC | T18: 4 | U18: 2
S19: Santos | T19: 4 | U19: 2
S20: 7 | T20: 1 | U20: 2
S21: Corinthians | T21: 1 | U21: 2
S22: Bahia | T22: 1 | U22: 2
S23: 8 | T23: 2 | U23: 1
S24: Sao Paulo | T24: 2 | U24: 1
S25: Flamengo RJ | T25: 2 | U25: 1
S26: 9 | T26: 2 | U26: 1
S27: Mirassol | T27: 2 | U27: 1
S28: Vasco | T28: 2 | U28: 1
S29: 10 | T29: 4 | U29: 0
S30: Botafogo RJ | T30: 4 | U30: 0
S31: Cruzeiro | T31: 4 | U31: 0
S32: 11 | T32: 1 | U32: 0
S33: Bragantino | T33: 1 | U33: 0
S34: Atletico-MG | T34: 1 | U34: 0
S35: 12 | T35: 1 | U35: 1
S36: Flamengo RJ | T36: 1 | U36: 1
S37: Internacional | T37: 1 | U37: 1
S38: 13 | T38: 2 | U38: 2
S39: Remo | T39: 2 | U39: 2
S40: Mirassol | T40: 2 | U40: 2
...

Sheet MAPVAL
A3: ODDS CASA | B3: Soma de PLBACKC | C3: Soma de PLEMP | D3: Soma de PLBACKV | E3: Contagem
A4: 1,3-1,5 | B4: 0.6 | C4: -3 | D4: -2.5 | E4: 12
A5: 1,5-1,7 | B5: -1.5 | C5: 3 | D5: -7.75 | E5: 19
A6: 1,7-1,9 | B6: 2.08 | C6: -7 | D6: -1.37 | E6: 14
A7: 1,9-2,1 | B7: 2.69 | C7: -5 | D7: -3.4 | E7: 15
A8: 2,1-2,3 | B8: -2.25 | C8: -5.5 | D8: 5.5 | E8: 15
A9: 2,3-2,5 | B9: 4.54 | C9: -4 | D9: -3.8 | E9: 7
A10: 2,5-2,7 | B10: -6.43 | C10: 3.2 | D10: 2.55 | E10: 9
A11: 2,7-2,9 | B11: -5 | C11: 7.8 | D11: -2.18 | E11: 5
A12: 2,9-3,1 | B12: 5 | C12: -0.9 | D12: -4 | E12: 4
A13: 3,1-3,3 | B13: -2.9 | C13: 3.5 | D13: -1.4 | E13: 6
A14: 3,3-3,5 | B14: -3 | C14: 3.2 | D14: -0.8 | E14: 3
A15: 3,7-3,9 | B15: 7.2 | C15: -4 | D15: -2.04 | E15: 4
... A19: Total Geral | B19: -1.97 | C19: -11.7 | D19: -18.85 | E19: 116

Sheet BDBRA1
A1: Date | B1: HomeTeam | C1: AwayTeam | D1: FTHG | E1: FTAG | F1: FTR | G1: ODDC | H1: ODDE | I1: ODDV | J1: PTC | K1: PTV | L1: GC/ODDV | M1: GV/ODDC | N1: PESOPTC | O1: PESOPTV | P1: SLDC | Q1: SLDV | R1: PLBACKC | S1: PLBACKV | T1: PLEMP | U1: GOLEAC | V1: GOLEAV | W1: 0,5FT | X1: 1,5FT | Y1: 2,5FT | Z1: 3,5FT | AA1: 4,5FT | AB1: 5,5FT | AC1: AMBFT | AD1: MÊS | AE1: CONTAG | AF1: VITC | AG1: EMP | AH1: VITV | AI1: FAVC | AJ1: FAVV | AK1: p(H) | AL1: p(D) | AM1: p(A) | AN1: JUICE | AO1: CustGC | AP1: CustGV | AQ1: T | AR1: MPTC | AS1: MPTV | AT1: DPMPTC | AU1: DPMPTV | AV1: CVMPTC | AW1: CVMPTV | AX1: T1 | AY1: MGOLEFC | AZ1: MGOLESC | BA1: MGOLEFV | BB1: MGOLESV | BC1: T2 | BD1: MGC | BE1: MGV | BF1: DPMGC | BG1: DPMGV | BH1: CVMGC | BI1: CVMGV | BJ1: T3 | BK1: MGSC | BL1: MGSV | BM1: DPMGSC | BN1: DPMGSV | BO1: CVMGSC | BP1: CVMGSV | BQ1: T4 | BR1: FCAtC | BS1: FCAtV | BT1: FCDfC | BU1: FCDfV | BV1: FCSALDC | BW1: FCSALDV | BX1: T5 | BY1: ODDMC | BZ1: ODDMV | CA1: DPODDMC | CB1: DPODDMV | CC1: CVODDMC | CD1: CVODDMV | CE1: T6 | CF1: WR0,5FTC | CG1: WR0,5FTV | CH1: WR1,5FTC | CI1: WR1,5FTV | CJ1: WR2,5FTC | CK1: WR2,5FTV | CL1: WR3,5FTC | CM1: WR3,5FTV | CN1: WR4,5FTC | CO1: WR4,5FTV | CP1: WR5,5FTC | CQ1: WR5,5FTV | CR1: T7 | CS1: AMBFTC | CT1: AMBFTV | CU1: T8 | CV1: PESOGC | CW1: PESOGV | CX1: DPPGC | CY1: DPPGV | CZ1: CVPGC | DA1: CVPGV | DB1: T9 | DC1: CUSTGC | DD1: CUSTGV | DE1: DPCGC | DF1: DPCGV | DG1: CVCGC | DH1: CVCGV | DI1: T10 | DJ1: MPT*ODDC | DK1: MPT*ODDV | DL1: T11 | DM1: PLTTBCKC | DN1: PLTTBCKV | DO1: PLEMPC | DP1: PLEMPV
A2: 46050 | B2: Atletico-MG | C2: Palmeiras | D2: 2 | E2: 2 | F2: D | G2: 3 | H2: 3.1 | I2: 2.5 | J2: =IF(A2="","",IF(F2="H",3,IF(F2="D",1,0))) -> 1 | K2: =IF(A2="","",IF(F2="H",0,IF(F2="D",1,3))) -> 1 | L2: =IF(A2="","",D2/I2) -> 0.8 | M2: =IF(A2="","",E2/G2) -> 0.66666667 | N2: =IF(A2="","",Tabela1[[#This Row],[PTC]]*Tabela1[[#This Row],[ODDC]]) -> 3 | O2: =IF(A2="","",Tabela1[[#This Row],[PTV]]*Tabela1[[#This Row],[ODDV]]) -> 2.5 | P2: =IF(A2="","",D2-E2) -> 0 | Q2: =IF(A2="","",E2-D2) -> 0 | R2: =IF(A2="","",IF(F2="H",G2-1,-1)) -> -1 | S2: =IF(A2="","",IF(F2="A",I2-1,-1)) -> -1 | T2: =IF(A2="","",IF(F2="D",Tabela1[[#This Row],[ODDE]]-1,-1)) -> 2.1 | U2: =IF(A2="","",IF(AND(Tabela1[[#This Row],[FTHG]]>3,F2="H"),1,0)) -> 0 | V2: =IF(A2="","",IF(AND(Tabela1[[#This Row],[FTAG]]>3,F2="A"),1,0)) -> 0 | W2: =IF(A2="","",IF(D2+E2>0,1,0)) -> 1 | X2: =IF(A2="","",IF(D2+E2>1,1,0)) -> 1 | Y2: =IF(A2="","",IF(D2+E2>2,1,0)) -> 1 | Z2: =IF(A2="","",IF(D2+E2>3,1,0)) -> 1 | AA2: =IF(A2="","",IF(D2+E2>4,1,0)) -> 0 | AB2: =IF(A2="","",IF(D2+E2>5,1,0)) -> 0 | AC2: =IF(A2="","",IFERROR(IF(AND(D2>0,E2>0),1,0),0)) -> 1 | AD2: =IF(A2="","",UPPER(TEXT(A2,"MMM"))) -> JAN | AE2: =IF(A2="","",COUNT($N$2:N2)) -> 1 | AF2: =IF(A2="","",IF(F2="H",1,0)) -> 0 | AG2: =IF(A2="","",IF(F2="D",1,0)) -> 1 | AH2: =IF(A2="","",IF(F2="A",1,0)) -> 0 | AI2: =IF(A2="","",IF(G2<1.21,"1,01-1,2",IF(G2<1.41,"1,21-1,4",IF(G2<1.71,"1,41-1,7",IF(G2<2.01,"1,71-2,0",IF(G2<2.41,"2,01-2,4",IF(G2<3.01,"2,41-3,0",IF(G2<4.01,"3,01-4.0",IF(G2<5.51,"4,01-5,5",IF(G2<9.01,"5,51-9,0",IF(G2<16.01,"9,01-16","Z16-99"))))))))))) -> 2,41-3,0 | AJ2: =IF(A2="","",IF(I2<1.21,"1,01-1,2",IF(I2<1.41,"1,21-1,4",IF(I2<1.71,"1,41-1,7",IF(I2<2.01,"1,71-2,0",IF(I2<2.41,"2,01-2,4",IF(I2<3.01,"2,41-3,0",IF(I2<4.01,"3,01-4.0",IF(I2<5.51,"4,01-5,5",IF(I2<9.01,"5,51-9,0",IF(I2<16.01,"9,01-16","Z16-99"))))))))))) -> 2,41-3,0 | AK2: =IF(A2="","",1/Tabela1[[#This Row],[ODDC]]) -> 0.33333333 | AL2: =IF(A2="","",1/Tabela1[[#This Row],[ODDE]]) -> 0.32258065 | AM2: =IF(A2="","",1/Tabela1[[#This Row],[ODDV]]) -> 0.4 | AN2: =IF(A2="","",1-(Tabela1[[#This Row],[p(H)]]+Tabela1[[#This Row],[p(D)]]+Tabela1[[#This Row],[p(A)]])) -> -0.055913978 | AO2: =IF(A2="","",IFERROR(Tabela1[[#This Row],[p(H)]]/Tabela1[[#This Row],[FTHG]],1)) -> 0.16666667 | AP2: =IF(A2="","",IFERROR(Tabela1[[#This Row],[p(A)]]/Tabela1[[#This Row],[FTAG]],1)) -> 0.2 | AQ2: Athletico-PR | AR2: =AVERAGEIF($B$2:$B$1203,Tabela2[[#This Row],[T]],$J$2:$J$1214) -> 2.5 | AS2: =AVERAGEIF($C$2:$C$1203,Tabela2[[#This Row],[T]],$K$2:$K$1214) -> 0.66666667 | AT2: {=_xlfn.STDEV.S(IF($B$2:$B$1203=Tabela2[[#This Row],[T]],$J$2:$J$1203))} -> 1.2247449 | AU2: {=_xlfn.STDEV.S(IF($C$2:$C$1203=Tabela2[[#This Row],[T]],$K$2:$K$1203))} -> 1.2110601 | AV2: =Tabela2[[#This Row],[DPMPTC]]/Tabela2[[#This Row],[MPTC]] -> 0.48989795 | AW2: =Tabela2[[#This Row],[DPMPTV]]/Tabela2[[#This Row],[MPTV]] -> 1.8165902 | AX2: =Tabela2[[#This Row],[T]] -> Athletico-PR | AY2: =AVERAGEIF($B$2:$B$1203,Tabela2[[#This Row],[T]],$U$2:$U$1194) -> 0.16666667 | AZ2: =AVERAGEIF($B$2:$B$1203,Tabela2[[#This Row],[T]],$V$2:$V$1194) -> 0 | BA2: =AVERAGEIF($C$2:$C$1203,Tabela2[[#This Row],[T1]],$V$2:$V$1194) -> 0 | BB2: =AVERAGEIF($C$2:$C$1203,Tabela2[[#This Row],[T]],$U$2:$U$1194) -> 0 | BC2: =Tabela2[[#This Row],[T]] -> Athletico-PR | BD2: =AVERAGEIF($B$2:$B$1203,Tabela2[[#This Row],[T]],$D$2:$D$1203) -> 2 | BE2: =AVERAGEIF($C$2:$C$1203,Tabela2[[#This Row],[T]],$E$2:$E$1203) -> 0.83333333 | BF2: {=_xlfn.STDEV.S(IF($B$2:$B$1203=Tabela2[[#This Row],[T]],$D$2:$D$1203))} -> 1.2649111 | BG2: {=_xlfn.STDEV.S(IF($C$2:$C$1203=Tabela2[[#This Row],[T]],$E$2:$E$1203))} -> 0.75277265 | BH2: =BF2/BD2 -> 0.63245553 | BI2: =BG2/BE2 -> 0.90332718 | BJ2: =Tabela2[[#This Row],[T]] -> Athletico-PR | BK2: =AVERAGEIF($B$2:$B$1203,Tabela2[[#This Row],[T]],$E$2:$E$1203) -> 0.66666667 | BL2: =AVERAGEIF($C$2:$C$1203,Tabela2[[#This Row],[T]],$D$2:$D$1203) -> 1.6666667 | BM2: {=_xlfn.STDEV.S(IF($B$2:$B$1203=Tabela2[[#This Row],[T]],$E$2:$E$1203))} -> 0.51639778 | BN2: {=_xlfn.STDEV.S(IF($C$2:$C$1203=Tabela2[[#This Row],[T]],$D$2:$D$1203))} -> 1.2110601 | BO2: =BM2/BK2 -> 0.77459667 | BP2: =BN2/BL2 -> 0.72663608 | BQ2: =Tabela2[[#This Row],[T]] -> Athletico-PR | BR2: =BD2/$BD$22 -> 1.2445366 | BS2: =BE2/$BE$22 -> 0.80009144 | BT2: =BK2/$BK$22 -> 0.63905055 | BU2: =BL2/$BL$22 -> 1.0481396 | BV2: =BR2-BT2 -> 0.60548608 | BW2: =BS2-BU2 -> -0.24804811 | BX2: =Tabela2[[#This Row],[T]] -> Athletico-PR | BY2: =AVERAGEIF($B$2:$B$1469,Tabela2[[#This Row],[T]],$G$2:$G$1214) -> 1.9733333 | BZ2: =AVERAGEIF($C$2:$C$1469,Tabela2[[#This Row],[T]],$I$2:$I$1214) -> 4.5166667 | CA2: {=_xlfn.STDEV.S(IF($B$2:$B$1469=Tabela2[[#This Row],[T]],$G$2:$G$1183))} -> 0.37961384 | CB2: {=_xlfn.STDEV.S(IF($C$2:$C1469=Tabela2[[#This Row],[T]],$I$2:$I$1183))} -> 1.1210114 | CC2: =CA2/BY2 -> 0.19237188 | CD2: =CB2/BZ2 -> 0.24819442 | CE2: =Tabela2[[#This Row],[T]] -> Athletico-PR | CF2: =AVERAGEIF($B$2:$B$1469,Tabela2[[#This Row],[T]],$W$2:$W$1203) -> 1 | CG2: =AVERAGEIF($C$2:$C$1469,Tabela2[[#This Row],[T]],$W$2:$W$1203) -> 1 | CH2: =AVERAGEIF($B$2:$B$1469,Tabela2[[#This Row],[T]],$X$2:$X$1203) -> 0.83333333 | CI2: =AVERAGEIF($C$2:$C$1469,Tabela2[[#This Row],[T]],$X$2:$X$1183) -> 0.66666667 | CJ2: =AVERAGEIF($B$2:$B$1469,Tabela2[[#This Row],[T]],$Y$2:$Y$1203) -> 0.5 | CK2: =AVERAGEIF($C$2:$C$1469,Tabela2[[#This Row],[T]],$Y$2:$Y$1203) -> 0.5 | CL2: =AVERAGEIF($B$2:$B$1469,Tabela2[[#This Row],[T]],$Z$2:$Z$1203) -> 0.16666667 | CM2: =AVERAGEIF($C$2:$C$1469,Tabela2[[#This Row],[T]],$Z$2:$Z$1183) -> 0.16666667 | CN2: =AVERAGEIF($B$2:$B$1469,Tabela2[[#This Row],[T]],$AA$2:$AA$1203) -> 0.16666667 | CO2: =AVERAGEIF($C$2:$C$1469,Tabela2[[#This Row],[T]],$AA$2:$AA$1203) -> 0.16666667 | CP2: =AVERAGEIF($B$2:$B$1469,Tabela2[[#This Row],[T]],$AB$2:$AB$1203) -> 0 | CQ2: =AVERAGEIF($C$2:$C$1469,Tabela2[[#This Row],[T]],$AB$2:$AB$1183) -> 0 | CR2: =Tabela2[[#This Row],[T]] -> Athletico-PR | CS2: =AVERAGEIF($B$2:$B$1469,Tabela2[[#This Row],[T]],$AC$2:$AC$1240) -> 0.5 | CT2: =AVERAGEIF($C$2:$C$1469,Tabela2[[#This Row],[T]],$AC$2:$AC$1220) -> 0.5 | CU2: =Tabela2[[#This Row],[T]] -> Athletico-PR | CV2: =AVERAGEIF($B$2:$B$1240,Tabela2[[#This Row],[T]],$L$2:$L$1205) -> 0.47501255 | CW2: =AVERAGEIF($C$2:$C$1240,Tabela2[[#This Row],[T]],$M$2:$M$1205) -> 0.43353757 | CX2: {=_xlfn.STDEV.S(IF($B$2:$B$1203=Tabela2[[#This Row],[T]],$L$2:$L$1203))} -> 0.33317511 | CY2: {=_xlfn.STDEV.S(IF($C$2:$C$1203=Tabela2[[#This Row],[T]],$M$2:$M$1203))} -> 0.4135833 | CZ2: =Tabela2[[#This Row],[DPPGC]]/Tabela2[[#This Row],[PESOGC]] -> 0.70140275 | DA2: =Tabela2[[#This Row],[DPPGV]]/Tabela2[[#This Row],[PESOGV]] -> 0.95397337 | DB2: =Tabela2[[#This Row],[T]] -> Athletico-PR | DC2: =AVERAGEIF($B$2:$B$1240,Tabela2[[#This Row],[T]],$AO$2:$AO$1205) -> 0.37426328 | DD2: =AVERAGEIF($C$2:$C$1240,Tabela2[[#This Row],[T]],$AP$2:$AP$1205) -> 0.48685233 | DE2: {=_xlfn.STDEV.S(IF($B$2:$B$1203=Tabela2[[#This Row],[T]],$AO$2:$AO$1203))} -> 0.31508167 | DF2: {=_xlfn.STDEV.S(IF($C$2:$C$1203=Tabela2[[#This Row],[T]],$AP$2:$AP$1203))} -> 0.40305062 | DG2: =Tabela2[[#This Row],[DPCGC]]/Tabela2[[#This Row],[CUSTGC]] -> 0.84187173 | DH2: =Tabela2[[#This Row],[DPCGV]]/Tabela2[[#This Row],[CUSTGV]] -> 0.82787037 | DI2: =Tabela2[[#This Row],[T]] -> Athletico-PR | DJ2: =AR2*BY2 -> 4.9333333 | DK2: =AS2*BZ2 -> 3.0111111 | DL2: =Tabela2[[#This Row],[T]] -> Athletico-PR | DM2: =SUMIF($B$2:$B$1340,Tabela2[[#This Row],[T]],$R$2:$R$1240) -> 3.27 | DN2: =SUMIF($C$2:$C$1340,Tabela2[[#This Row],[T]],$S$2:$S$1240) -> -2.1 | DO2: =SUMIF($B$2:$B$1240,Tabela2[[#This Row],[T]],$T$2:$T$1240) -> -6 | DP2: =SUMIF($C$2:$C$1240,Tabela2[[#This Row],[T]],$T$2:$T$1240) -> -2.7
A3: 46050 | B3: Coritiba | C3: Bragantino | D3: 0 | E3: 1 | F3: A | G3: 2.7 | H3: 2.82 | I3: 2.82 | J3: =IF(A3="","",IF(F3="H",3,IF(F3="D",1,0))) -> 0 | K3: =IF(A3="","",IF(F3="H",0,IF(F3="D",1,3))) -> 3 | L3: =IF(A3="","",D3/I3) -> 0 | M3: =IF(A3="","",E3/G3) -> 0.37037037 | N3: =IF(A3="","",Tabela1[[#This Row],[PTC]]*Tabela1[[#This Row],[ODDC]]) -> 0 | O3: =IF(A3="","",Tabela1[[#This Row],[PTV]]*Tabela1[[#This Row],[ODDV]]) -> 8.46 | P3: =IF(A3="","",D3-E3) -> -1 | Q3: =IF(A3="","",E3-D3) -> 1 | R3: =IF(A3="","",IF(F3="H",G3-1,-1)) -> -1 | S3: =IF(A3="","",IF(F3="A",I3-1,-1)) -> 1.82 | T3: =IF(A3="","",IF(F3="D",Tabela1[[#This Row],[ODDE]]-1,-1)) -> -1 | U3: =IF(A3="","",IF(AND(Tabela1[[#This Row],[FTHG]]>3,F3="H"),1,0)) -> 0 | V3: =IF(A3="","",IF(AND(Tabela1[[#This Row],[FTAG]]>3,F3="A"),1,0)) -> 0 | W3: =IF(A3="","",IF(D3+E3>0,1,0)) -> 1 | X3: =IF(A3="","",IF(D3+E3>1,1,0)) -> 0 | Y3: =IF(A3="","",IF(D3+E3>2,1,0)) -> 0 | Z3: =IF(A3="","",IF(D3+E3>3,1,0)) -> 0 | AA3: =IF(A3="","",IF(D3+E3>4,1,0)) -> 0 | AB3: =IF(A3="","",IF(D3+E3>5,1,0)) -> 0 | AC3: =IF(A3="","",IFERROR(IF(AND(D3>0,E3>0),1,0),0)) -> 0 | AD3: =IF(A3="","",UPPER(TEXT(A3,"MMM"))) -> JAN | AE3: =IF(A3="","",COUNT($N$2:N3)) -> 2 | AF3: =IF(A3="","",IF(F3="H",1,0)) -> 0 | AG3: =IF(A3="","",IF(F3="D",1,0)) -> 0 | AH3: =IF(A3="","",IF(F3="A",1,0)) -> 1 | AI3: =IF(A3="","",IF(G3<1.21,"1,01-1,2",IF(G3<1.41,"1,21-1,4",IF(G3<1.71,"1,41-1,7",IF(G3<2.01,"1,71-2,0",IF(G3<2.41,"2,01-2,4",IF(G3<3.01,"2,41-3,0",IF(G3<4.01,"3,01-4.0",IF(G3<5.51,"4,01-5,5",IF(G3<9.01,"5,51-9,0",IF(G3<16.01,"9,01-16","Z16-99"))))))))))) -> 2,41-3,0 | AJ3: =IF(A3="","",IF(I3<1.21,"1,01-1,2",IF(I3<1.41,"1,21-1,4",IF(I3<1.71,"1,41-1,7",IF(I3<2.01,"1,71-2,0",IF(I3<2.41,"2,01-2,4",IF(I3<3.01,"2,41-3,0",IF(I3<4.01,"3,01-4.0",IF(I3<5.51,"4,01-5,5",IF(I3<9.01,"5,51-9,0",IF(I3<16.01,"9,01-16","Z16-99"))))))))))) -> 2,41-3,0 | AK3: =IF(A3="","",1/Tabela1[[#This Row],[ODDC]]) -> 0.37037037 | AL3: =IF(A3="","",1/Tabela1[[#This Row],[ODDE]]) -> 0.35460993 | AM3: =IF(A3="","",1/Tabela1[[#This Row],[ODDV]]) -> 0.35460993 | AN3: =IF(A3="","",1-(Tabela1[[#This Row],[p(H)]]+Tabela1[[#This Row],[p(D)]]+Tabela1[[#This Row],[p(A)]])) -> -0.079590229 | AO3: =IF(A3="","",IFERROR(Tabela1[[#This Row],[p(H)]]/Tabela1[[#This Row],[FTHG]],1)) -> 1 | AP3: =IF(A3="","",IFERROR(Tabela1[[#This Row],[p(A)]]/Tabela1[[#This Row],[FTAG]],1)) -> 0.35460993 | AQ3: Atletico-MG | AR3: =AVERAGEIF($B$2:$B$1203,Tabela2[[#This Row],[T]],$J$2:$J$1214) -> 2.2 | AS3: =AVERAGEIF($C$2:$C$1203,Tabela2[[#This Row],[T]],$K$2:$K$1214) -> 0.42857143 | AT3: {=_xlfn.STDEV.S(IF($B$2:$B$1203=Tabela2[[#This Row],[T]],$J$2:$J$1203))} -> 1.0954451 | AU3: {=_xlfn.STDEV.S(IF($C$2:$C$1203=Tabela2[[#This Row],[T]],$K$2:$K$1203))} -> 1.1338934 | AV3: =Tabela2[[#This Row],[DPMPTC]]/Tabela2[[#This Row],[MPTC]] -> 0.4979296 | AW3: =Tabela2[[#This Row],[DPMPTV]]/Tabela2[[#This Row],[MPTV]] -> 2.6457513 | AX3: =Tabela2[[#This Row],[T]] -> Atletico-MG | AY3: =AVERAGEIF($B$2:$B$1203,Tabela2[[#This Row],[T]],$U$2:$U$1194) -> 0 | AZ3: =AVERAGEIF($B$2:$B$1203,Tabela2[[#This Row],[T]],$V$2:$V$1194) -> 0 | BA3: =AVERAGEIF($C$2:$C$1203,Tabela2[[#This Row],[T1]],$V$2:$V$1194) -> 0.14285714 | BB3: =AVERAGEIF($C$2:$C$1203,Tabela2[[#This Row],[T]],$U$2:$U$1194) -> 0 | BC3: =Tabela2[[#This Row],[T]] -> Atletico-MG | BD3: =AVERAGEIF($B$2:$B$1203,Tabela2[[#This Row],[T]],$D$2:$D$1203) -> 1.8 | BE3: =AVERAGEIF($C$2:$C$1203,Tabela2[[#This Row],[T]],$E$2:$E$1203) -> 0.71428571 | BF3: {=_xlfn.STDEV.S(IF($B$2:$B$1203=Tabela2[[#This Row],[T]],$D$2:$D$1203))} -> 0.83666003 | BG3: {=_xlfn.STDEV.S(IF($C$2:$C$1203=Tabela2[[#This Row],[T]],$E$2:$E$1203))} -> 1.4960265 | BH3: =BF3/BD3 -> 0.46481113 | BI3: =BG3/BE3 -> 2.0944371 | BJ3: =Tabela2[[#This Row],[T]] -> Atletico-MG | BK3: =AVERAGEIF($B$2:$B$1203,Tabela2[[#This Row],[T]],$E$2:$E$1203) -> 1.2 | BL3: =AVERAGEIF($C$2:$C$1203,Tabela2[[#This Row],[T]],$D$2:$D$1203) -> 1.2857143 | BM3: {=_xlfn.STDEV.S(IF($B$2:$B$1203=Tabela2[[#This Row],[T]],$E$2:$E$1203))} -> 1.3038405 | BN3: {=_xlfn.STDEV.S(IF($C$2:$C$1203=Tabela2[[#This Row],[T]],$D$2:$D$1203))} -> 0.75592895 | BO3: =BM3/BK3 -> 1.0865337 | BP3: =BN3/BL3 -> 0.58794474 | BQ3: =Tabela2[[#This Row],[T]] -> Atletico-MG | BR3: =BD3/$BD$22 -> 1.120083 | BS3: =BE3/$BE$22 -> 0.68579266 | BT3: =BK3/$BK$22 -> 1.150291 | BU3: =BL3/$BL$22 -> 0.8085648 | BV3: =BR3-BT3 -> -0.030208027 | BW3: =BS3-BU3 -> -0.12277214 | BX3: =Tabela2[[#This Row],[T]] -> Atletico-MG | BY3: =AVERAGEIF($B$2:$B$1469,Tabela2[[#This Row],[T]],$G$2:$G$1214) -> 2.164 | BZ3: =AVERAGEIF($C$2:$C$1469,Tabela2[[#This Row],[T]],$I$2:$I$1214) -> 3.6785714 | CA3: {=_xlfn.STDEV.S(IF($B$2:$B$1469=Tabela2[[#This Row],[T]],$G$2:$G$1183))} -> 0.57308813 | CB3: {=_xlfn.STDEV.S(IF($C$2:$C1470=Tabela2[[#This Row],[T]],$I$2:$I$1183))} -> 1.158252 | CC3: =CA3/BY3 -> 0.26482815 | CD3: =CB3/BZ3 -> 0.31486461 | CE3: =Tabela2[[#This Row],[T]] -> Atletico-MG | CF3: =AVERAGEIF($B$2:$B$1469,Tabela2[[#This Row],[T]],$W$2:$W$1203) -> 1 | CG3: =AVERAGEIF($C$2:$C$1469,Tabela2[[#This Row],[T]],$W$2:$W$1203) -> 1 | CH3: =AVERAGEIF($B$2:$B$1469,Tabela2[[#This Row],[T]],$X$2:$X$1203) -> 0.6 | CI3: =AVERAGEIF($C$2:$C$1469,Tabela2[[#This Row],[T]],$X$2:$X$1183) -> 0.57142857 | CJ3: =AVERAGEIF($B$2:$B$1469,Tabela2[[#This Row],[T]],$Y$2:$Y$1203) -> 0.6 | CK3: =AVERAGEIF($C$2:$C$1469,Tabela2[[#This Row],[T]],$Y$2:$Y$1203) -> 0.28571429 | CL3: =AVERAGEIF($B$2:$B$1469,Tabela2[[#This Row],[T]],$Z$2:$Z$1203) -> 0.4 | CM3: =AVERAGEIF($C$2:$C$1469,Tabela2[[#This Row],[T]],$Z$2:$Z$1183) -> 0.14285714 | CN3: =AVERAGEIF($B$2:$B$1469,Tabela2[[#This Row],[T]],$AA$2:$AA$1203) -> 0.2 | CO3: =AVERAGEIF($C$2:$C$1469,Tabela2[[#This Row],[T]],$AA$2:$AA$1203) -> 0 | CP3: =AVERAGEIF($B$2:$B$1469,Tabela2[[#This Row],[T]],$AB$2:$AB$1203) -> 0.2 | CQ3: =AVERAGEIF($C$2:$C$1469,Tabela2[[#This Row],[T]],$AB$2:$AB$1183) -> 0 | CR3: =Tabela2[[#This Row],[T]] -> Atletico-MG | CS3: =AVERAGEIF($B$2:$B$1469,Tabela2[[#This Row],[T]],$AC$2:$AC$1240) -> 0.6 | CT3: =AVERAGEIF($C$2:$C$1469,Tabela2[[#This Row],[T]],$AC$2:$AC$1220) -> 0.14285714 | CU3: =Tabela2[[#This Row],[T]] -> Atletico-MG | CV3: =AVERAGEIF($B$2:$B$1240,Tabela2[[#This Row],[T]],$L$2:$L$1205) -> 0.4740897 | CW3: =AVERAGEIF($C$2:$C$1240,Tabela2[[#This Row],[T]],$M$2:$M$1205) -> 0.23609444 | CX3: {=_xlfn.STDEV.S(IF($B$2:$B$1203=Tabela2[[#This Row],[T]],$L$2:$L$1203))} -> 0.22530836 | CY3: {=_xlfn.STDEV.S(IF($C$2:$C$1203=Tabela2[[#This Row],[T]],$M$2:$M$1203))} -> 0.45104625 | CZ3: =Tabela2[[#This Row],[DPPGC]]/Tabela2[[#This Row],[PESOGC]] -> 0.47524415 | DA3: =Tabela2[[#This Row],[DPPGV]]/Tabela2[[#This Row],[PESOGV]] -> 1.9104484 | DB3: =Tabela2[[#This Row],[T]] -> Atletico-MG | DC3: =AVERAGEIF($B$2:$B$1240,Tabela2[[#This Row],[T]],$AO$2:$AO$1205) -> 0.31469271 | DD3: =AVERAGEIF($C$2:$C$1240,Tabela2[[#This Row],[T]],$AP$2:$AP$1205) -> 0.77253629 | DE3: {=_xlfn.STDEV.S(IF($B$2:$B$1203=Tabela2[[#This Row],[T]],$AO$2:$AO$1203))} -> 0.14296174 | DF3: {=_xlfn.STDEV.S(IF($C$2:$C$1203=Tabela2[[#This Row],[T]],$AP$2:$AP$1203))} -> 0.39194647 | DG3: =Tabela2[[#This Row],[DPCGC]]/Tabela2[[#This Row],[CUSTGC]] -> 0.45428994 | DH3: =Tabela2[[#This Row],[DPCGV]]/Tabela2[[#This Row],[CUSTGV]] -> 0.50735024 | DI3: =Tabela2[[#This Row],[T]] -> Atletico-MG | DJ3: =AR3*BY3 -> 4.7608 | DK3: =AS3*BZ3 -> 1.5765306 | DL3: =Tabela2[[#This Row],[T]] -> Atletico-MG | DM3: =SUMIF($B$2:$B$1340,Tabela2[[#This Row],[T]],$R$2:$R$1240) -> 1.41 | DN3: =SUMIF($C$2:$C$1340,Tabela2[[#This Row],[T]],$S$2:$S$1240) -> -4.8 | DO3: =SUMIF($B$2:$B$1240,Tabela2[[#This Row],[T]],$T$2:$T$1240) -> 2.6 | DP3: =SUMIF($C$2:$C$1240,Tabela2[[#This Row],[T]],$T$2:$T$1240) -> -7
A4: 46050 | B4: Internacional | C4: Athletico-PR | D4: 0 | E4: 1 | F4: A | G4: 1.96 | H4: 3.25 | I4: 3.9 | J4: =IF(A4="","",IF(F4="H",3,IF(F4="D",1,0))) -> 0 | K4: =IF(A4="","",IF(F4="H",0,IF(F4="D",1,3))) -> 3 | L4: =IF(A4="","",D4/I4) -> 0 | M4: =IF(A4="","",E4/G4) -> 0.51020408 | N4: =IF(A4="","",Tabela1[[#This Row],[PTC]]*Tabela1[[#This Row],[ODDC]]) -> 0 | O4: =IF(A4="","",Tabela1[[#This Row],[PTV]]*Tabela1[[#This Row],[ODDV]]) -> 11.7 | P4: =IF(A4="","",D4-E4) -> -1 | Q4: =IF(A4="","",E4-D4) -> 1 | R4: =IF(A4="","",IF(F4="H",G4-1,-1)) -> -1 | S4: =IF(A4="","",IF(F4="A",I4-1,-1)) -> 2.9 | T4: =IF(A4="","",IF(F4="D",Tabela1[[#This Row],[ODDE]]-1,-1)) -> -1 | U4: =IF(A4="","",IF(AND(Tabela1[[#This Row],[FTHG]]>3,F4="H"),1,0)) -> 0 | V4: =IF(A4="","",IF(AND(Tabela1[[#This Row],[FTAG]]>3,F4="A"),1,0)) -> 0 | W4: =IF(A4="","",IF(D4+E4>0,1,0)) -> 1 | X4: =IF(A4="","",IF(D4+E4>1,1,0)) -> 0 | Y4: =IF(A4="","",IF(D4+E4>2,1,0)) -> 0 | Z4: =IF(A4="","",IF(D4+E4>3,1,0)) -> 0 | AA4: =IF(A4="","",IF(D4+E4>4,1,0)) -> 0 | AB4: =IF(A4="","",IF(D4+E4>5,1,0)) -> 0 | AC4: =IF(A4="","",IFERROR(IF(AND(D4>0,E4>0),1,0),0)) -> 0 | AD4: =IF(A4="","",UPPER(TEXT(A4,"MMM"))) -> JAN | AE4: =IF(A4="","",COUNT($N$2:N4)) -> 3 | AF4: =IF(A4="","",IF(F4="H",1,0)) -> 0 | AG4: =IF(A4="","",IF(F4="D",1,0)) -> 0 | AH4: =IF(A4="","",IF(F4="A",1,0)) -> 1 | AI4: =IF(A4="","",IF(G4<1.21,"1,01-1,2",IF(G4<1.41,"1,21-1,4",IF(G4<1.71,"1,41-1,7",IF(G4<2.01,"1,71-2,0",IF(G4<2.41,"2,01-2,4",IF(G4<3.01,"2,41-3,0",IF(G4<4.01,"3,01-4.0",IF(G4<5.51,"4,01-5,5",IF(G4<9.01,"5,51-9,0",IF(G4<16.01,"9,01-16","Z16-99"))))))))))) -> 1,71-2,0 | AJ4: =IF(A4="","",IF(I4<1.21,"1,01-1,2",IF(I4<1.41,"1,21-1,4",IF(I4<1.71,"1,41-1,7",IF(I4<2.01,"1,71-2,0",IF(I4<2.41,"2,01-2,4",IF(I4<3.01,"2,41-3,0",IF(I4<4.01,"3,01-4.0",IF(I4<5.51,"4,01-5,5",IF(I4<9.01,"5,51-9,0",IF(I4<16.01,"9,01-16","Z16-99"))))))))))) -> 3,01-4.0 | AK4: =IF(A4="","",1/Tabela1[[#This Row],[ODDC]]) -> 0.51020408 | AL4: =IF(A4="","",1/Tabela1[[#This Row],[ODDE]]) -> 0.30769231 | AM4: =IF(A4="","",1/Tabela1[[#This Row],[ODDV]]) -> 0.25641026 | AN4: =IF(A4="","",1-(Tabela1[[#This Row],[p(H)]]+Tabela1[[#This Row],[p(D)]]+Tabela1[[#This Row],[p(A)]])) -> -0.074306646 | AO4: =IF(A4="","",IFERROR(Tabela1[[#This Row],[p(H)]]/Tabela1[[#This Row],[FTHG]],1)) -> 1 | AP4: =IF(A4="","",IFERROR(Tabela1[[#This Row],[p(A)]]/Tabela1[[#This Row],[FTAG]],1)) -> 0.25641026 | AQ4: Bahia | AR4: =AVERAGEIF($B$2:$B$1203,Tabela2[[#This Row],[T]],$J$2:$J$1214) -> 1.6 | AS4: =AVERAGEIF($C$2:$C$1203,Tabela2[[#This Row],[T]],$K$2:$K$1214) -> 2 | AT4: {=_xlfn.STDEV.S(IF($B$2:$B$1203=Tabela2[[#This Row],[T]],$J$2:$J$1203))} -> 1.3416408 | AU4: {=_xlfn.STDEV.S(IF($C$2:$C$1203=Tabela2[[#This Row],[T]],$K$2:$K$1203))} -> 1.5491933 | AV4: =Tabela2[[#This Row],[DPMPTC]]/Tabela2[[#This Row],[MPTC]] -> 0.83852549 | AW4: =Tabela2[[#This Row],[DPMPTV]]/Tabela2[[#This Row],[MPTV]] -> 0.77459667 | AX4: =Tabela2[[#This Row],[T]] -> Bahia | AY4: =AVERAGEIF($B$2:$B$1203,Tabela2[[#This Row],[T]],$U$2:$U$1194) -> 0 | AZ4: =AVERAGEIF($B$2:$B$1203,Tabela2[[#This Row],[T]],$V$2:$V$1194) -> 0 | BA4: =AVERAGEIF($C$2:$C$1203,Tabela2[[#This Row],[T1]],$V$2:$V$1194) -> 0 | BB4: =AVERAGEIF($C$2:$C$1203,Tabela2[[#This Row],[T]],$U$2:$U$1194) -> 0.16666667 | BC4: =Tabela2[[#This Row],[T]] -> Bahia | BD4: =AVERAGEIF($B$2:$B$1203,Tabela2[[#This Row],[T]],$D$2:$D$1203) -> 1.6 | BE4: =AVERAGEIF($C$2:$C$1203,Tabela2[[#This Row],[T]],$E$2:$E$1203) -> 1.1666667 | BF4: {=_xlfn.STDEV.S(IF($B$2:$B$1203=Tabela2[[#This Row],[T]],$D$2:$D$1203))} -> 0.89442719 | BG4: {=_xlfn.STDEV.S(IF($C$2:$C$1203=Tabela2[[#This Row],[T]],$E$2:$E$1203))} -> 0.75277265 | BH4: =BF4/BD4 -> 0.55901699 | BI4: =IFERROR(BG4/BE4,0) -> 0.6452337 | BJ4: =Tabela2[[#This Row],[T]] -> Bahia | BK4: =AVERAGEIF($B$2:$B$1203,Tabela2[[#This Row],[T]],$E$2:$E$1203) -> 0.8 | BL4: =AVERAGEIF($C$2:$C$1203,Tabela2[[#This Row],[T]],$D$2:$D$1203) -> 1.3333333 | BM4: {=_xlfn.STDEV.S(IF($B$2:$B$1203=Tabela2[[#This Row],[T]],$E$2:$E$1203))} -> 0.83666003 | BN4: {=_xlfn.STDEV.S(IF($C$2:$C$1203=Tabela2[[#This Row],[T]],$D$2:$D$1203))} -> 1.5055453 | BO4: =BM4/BK4 -> 1.045825 | BP4: =BN4/BL4 -> 1.129159 | BQ4: =Tabela2[[#This Row],[T]] -> Bahia | BR4: =BD4/$BD$22 -> 0.99562931 | BS4: =BE4/$BE$22 -> 1.120128 | BT4: =BK4/$BK$22 -> 0.76686066 | BU4: =BL4/$BL$22 -> 0.83851164 | BV4: =BR4-BT4 -> 0.22876864 | BW4: =BS4-BU4 -> 0.28161637 | BX4: =Tabela2[[#This Row],[T]] -> Bahia | BY4: =AVERAGEIF($B$2:$B$1469,Tabela2[[#This Row],[T]],$G$2:$G$1214) -> 1.908 | BZ4: =AVERAGEIF($C$2:$C$1469,Tabela2[[#This Row],[T]],$I$2:$I$1214) -> 3.8133333 | CA4: {=_xlfn.STDEV.S(IF($B$2:$B$1469=Tabela2[[#This Row],[T]],$G$2:$G$1183))} -> 0.36162135 | CB4: {=_xlfn.STDEV.S(IF($C$2:$C1471=Tabela2[[#This Row],[T]],$I$2:$I$1183))} -> 1.4616657 | CC4: =CA4/BY4 -> 0.18952901 | CD4: =CB4/BZ4 -> 0.38330395 | CE4: =Tabela2[[#This Row],[T]] -> Bahia | CF4: =AVERAGEIF($B$2:$B$1469,Tabela2[[#This Row],[T]],$W$2:$W$1203) -> 1 | CG4: =AVERAGEIF($C$2:$C$1469,Tabela2[[#This Row],[T]],$W$2:$W$1203) -> 1 | CH4: =AVERAGEIF($B$2:$B$1469,Tabela2[[#This Row],[T]],$X$2:$X$1203) -> 1 | CI4: =AVERAGEIF($C$2:$C$1469,Tabela2[[#This Row],[T]],$X$2:$X$1183) -> 0.66666667 | CJ4: =AVERAGEIF($B$2:$B$1469,Tabela2[[#This Row],[T]],$Y$2:$Y$1203) -> 0.4 | CK4: =AVERAGEIF($C$2:$C$1469,Tabela2[[#This Row],[T]],$Y$2:$Y$1203) -> 0.5 | CL4: =AVERAGEIF($B$2:$B$1469,Tabela2[[#This Row],[T]],$Z$2:$Z$1203) -> 0 | CM4: =AVERAGEIF($C$2:$C$1469,Tabela2[[#This Row],[T]],$Z$2:$Z$1183) -> 0.16666667 | CN4: =AVERAGEIF($B$2:$B$1469,Tabela2[[#This Row],[T]],$AA$2:$AA$1203) -> 0 | CO4: =AVERAGEIF($C$2:$C$1469,Tabela2[[#This Row],[T]],$AA$2:$AA$1203) -> 0.16666667 | CP4: =AVERAGEIF($B$2:$B$1469,Tabela2[[#This Row],[T]],$AB$2:$AB$1203) -> 0 | CQ4: =AVERAGEIF($C$2:$C$1469,Tabela2[[#This Row],[T]],$AB$2:$AB$1183) -> 0 | CR4: =Tabela2[[#This Row],[T]] -> Bahia | CS4: =AVERAGEIF($B$2:$B$1469,Tabela2[[#This Row],[T]],$AC$2:$AC$1240) -> 0.6 | CT4: =AVERAGEIF($C$2:$C$1469,Tabela2[[#This Row],[T]],$AC$2:$AC$1220) -> 0.5 | CU4: =Tabela2[[#This Row],[T]] -> Bahia | CV4: =AVERAGEIF($B$2:$B$1240,Tabela2[[#This Row],[T]],$L$2:$L$1205) -> 0.3663325 | CW4: =AVERAGEIF($C$2:$C$1240,Tabela2[[#This Row],[T]],$M$2:$M$1205) -> 0.53256401 | CX4: {=_xlfn.STDEV.S(IF($B$2:$B$1203=Tabela2[[#This Row],[T]],$L$2:$L$1203))} -> 0.16551108 | CY4: {=_xlfn.STDEV.S(IF($C$2:$C$1203=Tabela2[[#This Row],[T]],$M$2:$M$1203))} -> 0.35512972 | CZ4: =Tabela2[[#This Row],[DPPGC]]/Tabela2[[#This Row],[PESOGC]] -> 0.45180561 | DA4: =Tabela2[[#This Row],[DPPGV]]/Tabela2[[#This Row],[PESOGV]] -> 0.66683011 | DB4: =Tabela2[[#This Row],[T]] -> Bahia | DC4: =AVERAGEIF($B$2:$B$1240,Tabela2[[#This Row],[T]],$AO$2:$AO$1205) -> 0.39921173 | DD4: =AVERAGEIF($C$2:$C$1240,Tabela2[[#This Row],[T]],$AP$2:$AP$1205) -> 0.38039471 | DE4: {=_xlfn.STDEV.S(IF($B$2:$B$1203=Tabela2[[#This Row],[T]],$AO$2:$AO$1203))} -> 0.15991302 | DF4: {=_xlfn.STDEV.S(IF($C$2:$C$1203=Tabela2[[#This Row],[T]],$AP$2:$AP$1203))} -> 0.32134458 | DG4: =Tabela2[[#This Row],[DPCGC]]/Tabela2[[#This Row],[CUSTGC]] -> 0.40057194 | DH4: =Tabela2[[#This Row],[DPCGV]]/Tabela2[[#This Row],[CUSTGV]] -> 0.84476616 | DI4: =Tabela2[[#This Row],[T]] -> Bahia | DJ4: =AR4*BY4 -> 3.0528 | DK4: =AS4*BZ4 -> 7.6266667 | DL4: =Tabela2[[#This Row],[T]] -> Bahia | DM4: =SUMIF($B$2:$B$1340,Tabela2[[#This Row],[T]],$R$2:$R$1240) -> -1.63 | DN4: =SUMIF($C$2:$C$1340,Tabela2[[#This Row],[T]],$S$2:$S$1240) -> 8.03 | DO4: =SUMIF($B$2:$B$1240,Tabela2[[#This Row],[T]],$T$2:$T$1240) -> 1.9 | DP4: =SUMIF($C$2:$C$1240,Tabela2[[#This Row],[T]],$T$2:$T$1240) -> -6
